Workbook

Sheet Dashboard
A1: FIFA World Cup 2026 Tracker
A2: Enter scores in the yellow columns on Matches and Knockout; standings, leaders, and dashboard KPIs update automatically.
A4: Tournament dates | B4: 11 Jun – 19 Jul 2026 | D4: Completed group matches | E4: =COUNTIF(Matches!$I$2:$I$73,TRUE) -> 72
A5: Host countries | B5: Canada, Mexico, USA | D5: Group matches remaining | E5: =72-E4 -> 0
A6: Teams | B6: 48 | D6: Goals entered | E6: =SUM(Matches!$G$2:$H$73)+SUM('Knockout Data'!$H$2:$I$33) -> 216
A7: Groups | B7: 12 groups of 4 | D7: Average goals / played | E7: =IF(E4=0,"",E6/E4) -> 3
A8: Total matches | B8: 104 | D8: Knockout matches completed | E8: {=SUMPRODUCT(--('Knockout Data'!$J$2:$J$33<>""))} -> 1
A9: Advancement | B9: Top 2 + 8 best third-place teams | D9: Current champion | E9: =IFERROR(_xlfn.XLOOKUP(104,'Knockout Data'!$A$2:$A$33,'Knockout Data'!$J$2:$J$33),"")
A12: Next / upcoming fixtures
A13: Date | B13: Stage | C13: Group | D13: Team 1 | E13: Team 2 | F13: Venue
A14: {=_xlfn.TAKE(_xlfn._xlws.FILTER(CHOOSE({1,2,3,4,5,6},Matches!$B$2:$B$73,Matches!$C$2:$C$73,Matches!$D$2:$D$73,Matches!$E$2:$E$73,Matches!$F$2:$F$73,Matches!$K$2:$K$73),Matches!$I$2:$I$73=FALSE),10)} -> #VALUE!
A27: Current group leaders
A28: Group | B28: Leader | C28: Points
A29: A | B29: {=IFERROR(INDEX(_xlfn._xlws.FILTER('Standings Data'!$B$2:$B$49,('Standings Data'!$A$2:$A$49="A")*('Standings Data'!$K$2:$K$49=1)),1),"")} -> Mexico | C29: =IFERROR(_xlfn.XLOOKUP(B29,'Standings Data'!$B$2:$B$49,'Standings Data'!$J$2:$J$49),"") -> 9
A30: B | B30: {=IFERROR(INDEX(_xlfn._xlws.FILTER('Standings Data'!$B$2:$B$49,('Standings Data'!$A$2:$A$49="B")*('Standings Data'!$K$2:$K$49=1)),1),"")} -> Switzerland | C30: =IFERROR(_xlfn.XLOOKUP(B30,'Standings Data'!$B$2:$B$49,'Standings Data'!$J$2:$J$49),"") -> 7
A31: C | B31: {=IFERROR(INDEX(_xlfn._xlws.FILTER('Standings Data'!$B$2:$B$49,('Standings Data'!$A$2:$A$49="C")*('Standings Data'!$K$2:$K$49=1)),1),"")} -> Brazil | C31: =IFERROR(_xlfn.XLOOKUP(B31,'Standings Data'!$B$2:$B$49,'Standings Data'!$J$2:$J$49),"") -> 7
A32: D | B32: {=IFERROR(INDEX(_xlfn._xlws.FILTER('Standings Data'!$B$2:$B$49,('Standings Data'!$A$2:$A$49="D")*('Standings Data'!$K$2:$K$49=1)),1),"")} -> USA | C32: =IFERROR(_xlfn.XLOOKUP(B32,'Standings Data'!$B$2:$B$49,'Standings Data'!$J$2:$J$49),"") -> 6
A33: E | B33: {=IFERROR(INDEX(_xlfn._xlws.FILTER('Standings Data'!$B$2:$B$49,('Standings Data'!$A$2:$A$49="E")*('Standings Data'!$K$2:$K$49=1)),1),"")} -> Germany | C33: =IFERROR(_xlfn.XLOOKUP(B33,'Standings Data'!$B$2:$B$49,'Standings Data'!$J$2:$J$49),"") -> 6
A34: F | B34: {=IFERROR(INDEX(_xlfn._xlws.FILTER('Standings Data'!$B$2:$B$49,('Standings Data'!$A$2:$A$49="F")*('Standings Data'!$K$2:$K$49=1)),1),"")} -> Netherlands | C34: =IFERROR(_xlfn.XLOOKUP(B34,'Standings Data'!$B$2:$B$49,'Standings Data'!$J$2:$J$49),"") -> 7
A35: G | B35: {=IFERROR(INDEX(_xlfn._xlws.FILTER('Standings Data'!$B$2:$B$49,('Standings Data'!$A$2:$A$49="G")*('Standings Data'!$K$2:$K$49=1)),1),"")} -> Belgium | C35: =IFERROR(_xlfn.XLOOKUP(B35,'Standings Data'!$B$2:$B$49,'Standings Data'!$J$2:$J$49),"") -> 5
A36: H | B36: {=IFERROR(INDEX(_xlfn._xlws.FILTER('Standings Data'!$B$2:$B$49,('Standings Data'!$A$2:$A$49="H")*('Standings Data'!$K$2:$K$49=1)),1),"")} -> Spain | C36: =IFERROR(_xlfn.XLOOKUP(B36,'Standings Data'!$B$2:$B$49,'Standings Data'!$J$2:$J$49),"") -> 7
A37: I | B37: {=IFERROR(INDEX(_xlfn._xlws.FILTER('Standings Data'!$B$2:$B$49,('Standings Data'!$A$2:$A$49="I")*('Standings Data'!$K$2:$K$49=1)),1),"")} -> France | C37: =IFERROR(_xlfn.XLOOKUP(B37,'Standings Data'!$B$2:$B$49,'Standings Data'!$J$2:$J$49),"") -> 9
A38: J | B38: {=IFERROR(INDEX(_xlfn._xlws.FILTER('Standings Data'!$B$2:$B$49,('Standings Data'!$A$2:$A$49="J")*('Standings Data'!$K$2:$K$49=1)),1),"")} -> Argentina | C38: =IFERROR(_xlfn.XLOOKUP(B38,'Standings Data'!$B$2:$B$49,'Standings Data'!$J$2:$J$49),"") -> 9
A39: K | B39: {=IFERROR(INDEX(_xlfn._xlws.FILTER('Standings Data'!$B$2:$B$49,('Standings Data'!$A$2:$A$49="K")*('Standings Data'!$K$2:$K$49=1)),1),"")} -> Colombia | C39: =IFERROR(_xlfn.XLOOKUP(B39,'Standings Data'!$B$2:$B$49,'Standings Data'!$J$2:$J$49),"") -> 7
A40: L | B40: {=IFERROR(INDEX(_xlfn._xlws.FILTER('Standings Data'!$B$2:$B$49,('Standings Data'!$A$2:$A$49="L")*('Standings Data'!$K$2:$K$49=1)),1),"")} -> England | C40: =IFERROR(_xlfn.XLOOKUP(B40,'Standings Data'!$B$2:$B$49,'Standings Data'!$J$2:$J$49),"") -> 7

Sheet Standings
A1: Group A standings | O1: Group G standings | AC1: Third-place ranking
A2: Team | B2: Pld | C2: W | D2: D | E2: L | F2: GF | G2: GA | H2: GD | I2: Pts | J2: Rank | K2: Position | L2: Advance Status | O2: Team | P2: Pld | Q2: W | R2: D | S2: L | T2: GF | U2: GA | V2: GD | W2: Pts | X2: Rank | Y2: Position | Z2: Advance Status | AC2: Rank | AD2: Team | AE2: Group | AF2: Pts | AG2: GD | AH2: GF | AI2: Status
A3: {=IFERROR(INDEX(_xlfn.SORTBY(_xlfn._xlws.FILTER('Standings Data'!$B$2:$M$49,'Standings Data'!$A$2:$A$49="A"),_xlfn._xlws.FILTER('Standings Data'!$K$2:$K$49,'Standings Data'!$A$2:$A$49="A"),1),1,1),"")} -> Mexico | B3: {=IFERROR(INDEX(_xlfn.SORTBY(_xlfn._xlws.FILTER('Standings Data'!$B$2:$M$49,'Standings Data'!$A$2:$A$49="A"),_xlfn._xlws.FILTER('Standings Data'!$K$2:$K$49,'Standings Data'!$A$2:$A$49="A"),1),1,2),"")} -> 3 | C3: {=IFERROR(INDEX(_xlfn.SORTBY(_xlfn._xlws.FILTER('Standings Data'!$B$2:$M$49,'Standings Data'!$A$2:$A$49="A"),_xlfn._xlws.FILTER('Standings Data'!$K$2:$K$49,'Standings Data'!$A$2:$A$49="A"),1),1,3),"")} -> 3 | D3: {=IFERROR(INDEX(_xlfn.SORTBY(_xlfn._xlws.FILTER('Standings Data'!$B$2:$M$49,'Standings Data'!$A$2:$A$49="A"),_xlfn._xlws.FILTER('Standings Data'!$K$2:$K$49,'Standings Data'!$A$2:$A$49="A"),1),1,4),"")} -> 0 | E3: {=IFERROR(INDEX(_xlfn.SORTBY(_xlfn._xlws.FILTER('Standings Data'!$B$2:$M$49,'Standings Data'!$A$2:$A$49="A"),_xlfn._xlws.FILTER('Standings Data'!$K$2:$K$49,'Standings Data'!$A$2:$A$49="A"),1),1,5),"")} -> 0 | F3: {=IFERROR(INDEX(_xlfn.SORTBY(_xlfn._xlws.FILTER('Standings Data'!$B$2:$M$49,'Standings Data'!$A$2:$A$49="A"),_xlfn._xlws.FILTER('Standings Data'!$K$2:$K$49,'Standings Data'!$A$2:$A$49="A"),1),1,6),"")} -> 6 | G3: {=IFERROR(INDEX(_xlfn.SORTBY(_xlfn._xlws.FILTER('Standings Data'!$B$2:$M$49,'Standings Data'!$A$2:$A$49="A"),_xlfn._xlws.FILTER('Standings Data'!$K$2:$K$49,'Standings Data'!$A$2:$A$49="A"),1),1,7),"")} -> 0 | H3: {=IFERROR(INDEX(_xlfn.SORTBY(_xlfn._xlws.FILTER('Standings Data'!$B$2:$M$49,'Standings Data'!$A$2:$A$49="A"),_xlfn._xlws.FILTER('Standings Data'!$K$2:$K$49,'Standings Data'!$A$2:$A$49="A"),1),1,8),"")} -> 6 | I3: {=IFERROR(INDEX(_xlfn.SORTBY(_xlfn._xlws.FILTER('Standings Data'!$B$2:$M$49,'Standings Data'!$A$2:$A$49="A"),_xlfn._xlws.FILTER('Standings Data'!$K$2:$K$49,'Standings Data'!$A$2:$A$49="A"),1),1,9),"")} -> 9 | J3: {=IFERROR(INDEX(_xlfn.SORTBY(_xlfn._xlws.FILTER('Standings Data'!$B$2:$M$49,'Standings Data'!$A$2:$A$49="A"),_xlfn._xlws.FILTER('Standings Data'!$K$2:$K$49,'Standings Data'!$A$2:$A$49="A"),1),1,10),"")} -> 1 | K3: {=IFERROR(INDEX(_xlfn.SORTBY(_xlfn._xlws.FILTER('Standings Data'!$B$2:$M$49,'Standings Data'!$A$2:$A$49="A"),_xlfn._xlws.FILTER('Standings Data'!$K$2:$K$49,'Standings Data'!$A$2:$A$49="A"),1),1,11),"")} -> A1 | L3: {=IFERROR(INDEX(_xlfn.SORTBY(_xlfn._xlws.FILTER('Standings Data'!$B$2:$M$49,'Standings Data'!$A$2:$A$49="A"),_xlfn._xlws.FILTER('Standings Data'!$K$2:$K$49,'Standings Data'!$A$2:$A$49="A"),1),1,12),"")} -> Qualified | O3: {=IFERROR(INDEX(_xlfn.SORTBY(_xlfn._xlws.FILTER('Standings Data'!$B$2:$M$49,'Standings Data'!$A$2:$A$49="G"),_xlfn._xlws.FILTER('Standings Data'!$K$2:$K$49,'Standings Data'!$A$2:$A$49="G"),1),1,1),"")} -> Belgium | P3: {=IFERROR(INDEX(_xlfn.SORTBY(_xlfn._xlws.FILTER('Standings Data'!$B$2:$M$49,'Standings Data'!$A$2:$A$49="G"),_xlfn._xlws.FILTER('Standings Data'!$K$2:$K$49,'Standings Data'!$A$2:$A$49="G"),1),1,2),"")} -> 3 | Q3: {=IFERROR(INDEX(_xlfn.SORTBY(_xlfn._xlws.FILTER('Standings Data'!$B$2:$M$49,'Standings Data'!$A$2:$A$49="G"),_xlfn._xlws.FILTER('Standings Data'!$K$2:$K$49,'Standings Data'!$A$2:$A$49="G"),1),1,3),"")} -> 1 | R3: {=IFERROR(INDEX(_xlfn.SORTBY(_xlfn._xlws.FILTER('Standings Data'!$B$2:$M$49,'Standings Data'!$A$2:$A$49="G"),_xlfn._xlws.FILTER('Standings Data'!$K$2:$K$49,'Standings Data'!$A$2:$A$49="G"),1),1,4),"")} -> 2 | S3: {=IFERROR(INDEX(_xlfn.SORTBY(_xlfn._xlws.FILTER('Standings Data'!$B$2:$M$49,'Standings Data'!$A$2:$A$49="G"),_xlfn._xlws.FILTER('Standings Data'!$K$2:$K$49,'Standings Data'!$A$2:$A$49="G"),1),1,5),"")} -> 0 | T3: {=IFERROR(INDEX(_xlfn.SORTBY(_xlfn._xlws.FILTER('Standings Data'!$B$2:$M$49,'Standings Data'!$A$2:$A$49="G"),_xlfn._xlws.FILTER('Standings Data'!$K$2:$K$49,'Standings Data'!$A$2:$A$49="G"),1),1,6),"")} -> 6 | U3: {=IFERROR(INDEX(_xlfn.SORTBY(_xlfn._xlws.FILTER('Standings Data'!$B$2:$M$49,'Standings Data'!$A$2:$A$49="G"),_xlfn._xlws.FILTER('Standings Data'!$K$2:$K$49,'Standings Data'!$A$2:$A$49="G"),1),1,7),"")} -> 2 | V3: {=IFERROR(INDEX(_xlfn.SORTBY(_xlfn._xlws.FILTER('Standings Data'!$B$2:$M$49,'Standings Data'!$A$2:$A$49="G"),_xlfn._xlws.FILTER('Standings Data'!$K$2:$K$49,'Standings Data'!$A$2:$A$49="G"),1),1,8),"")} -> 4 | W3: {=IFERROR(INDEX(_xlfn.SORTBY(_xlfn._xlws.FILTER('Standings Data'!$B$2:$M$49,'Standings Data'!$A$2:$A$49="G"),_xlfn._xlws.FILTER('Standings Data'!$K$2:$K$49,'Standings Data'!$A$2:$A$49="G"),1),1,9),"")} -> 5 | X3: {=IFERROR(INDEX(_xlfn.SORTBY(_xlfn._xlws.FILTER('Standings Data'!$B$2:$M$49,'Standings Data'!$A$2:$A$49="G"),_xlfn._xlws.FILTER('Standings Data'!$K$2:$K$49,'Standings Data'!$A$2:$A$49="G"),1),1,10),"")} -> 1 | Y3: {=IFERROR(INDEX(_xlfn.SORTBY(_xlfn._xlws.FILTER('Standings Data'!$B$2:$M$49,'Standings Data'!$A$2:$A$49="G"),_xlfn._xlws.FILTER('Standings Data'!$K$2:$K$49,'Standings Data'!$A$2:$A$49="G"),1),1,11),"")} -> G1 | Z3: {=IFERROR(INDEX(_xlfn.SORTBY(_xlfn._xlws.FILTER('Standings Data'!$B$2:$M$49,'Standings Data'!$A$2:$A$49="G"),_xlfn._xlws.FILTER('Standings Data'!$K$2:$K$49,'Standings Data'!$A$2:$A$49="G"),1),1,12),"")} -> Qualified | AC3: ='Standings Data'!O2 -> 1 | AD3: ='Standings Data'!P2 -> Korea Republic | AE3: ='Standings Data'!Q2 -> A | AF3: ='Standings Data'!R2 -> 3 | AG3: ='Standings Data'!S2 -> -1 | AH3: ='Standings Data'!T2 -> 2 | AI3: ='Standings Data'!U2 -> Likely advances
A4: {=IFERROR(INDEX(_xlfn.SORTBY(_xlfn._xlws.FILTER('Standings Data'!$B$2:$M$49,'Standings Data'!$A$2:$A$49="A"),_xlfn._xlws.FILTER('Standings Data'!$K$2:$K$49,'Standings Data'!$A$2:$A$49="A"),1),2,1),"")} -> South Africa | B4: {=IFERROR(INDEX(_xlfn.SORTBY(_xlfn._xlws.FILTER('Standings Data'!$B$2:$M$49,'Standings Data'!$A$2:$A$49="A"),_xlfn._xlws.FILTER('Standings Data'!$K$2:$K$49,'Standings Data'!$A$2:$A$49="A"),1),2,2),"")} -> 3 | C4: {=IFERROR(INDEX(_xlfn.SORTBY(_xlfn._xlws.FILTER('Standings Data'!$B$2:$M$49,'Standings Data'!$A$2:$A$49="A"),_xlfn._xlws.FILTER('Standings Data'!$K$2:$K$49,'Standings Data'!$A$2:$A$49="A"),1),2,3),"")} -> 1 | D4: {=IFERROR(INDEX(_xlfn.SORTBY(_xlfn._xlws.FILTER('Standings Data'!$B$2:$M$49,'Standings Data'!$A$2:$A$49="A"),_xlfn._xlws.FILTER('Standings Data'!$K$2:$K$49,'Standings Data'!$A$2:$A$49="A"),1),2,4),"")} -> 1 | E4: {=IFERROR(INDEX(_xlfn.SORTBY(_xlfn._xlws.FILTER('Standings Data'!$B$2:$M$49,'Standings Data'!$A$2:$A$49="A"),_xlfn._xlws.FILTER('Standings Data'!$K$2:$K$49,'Standings Data'!$A$2:$A$49="A"),1),2,5),"")} -> 1 | F4: {=IFERROR(INDEX(_xlfn.SORTBY(_xlfn._xlws.FILTER('Standings Data'!$B$2:$M$49,'Standings Data'!$A$2:$A$49="A"),_xlfn._xlws.FILTER('Standings Data'!$K$2:$K$49,'Standings Data'!$A$2:$A$49="A"),1),2,6),"")} -> 2 | G4: {=IFERROR(INDEX(_xlfn.SORTBY(_xlfn._xlws.FILTER('Standings Data'!$B$2:$M$49,'Standings Data'!$A$2:$A$49="A"),_xlfn._xlws.FILTER('Standings Data'!$K$2:$K$49,'Standings Data'!$A$2:$A$49="A"),1),2,7),"")} -> 3 | H4: {=IFERROR(INDEX(_xlfn.SORTBY(_xlfn._xlws.FILTER('Standings Data'!$B$2:$M$49,'Standings Data'!$A$2:$A$49="A"),_xlfn._xlws.FILTER('Standings Data'!$K$2:$K$49,'Standings Data'!$A$2:$A$49="A"),1),2,8),"")} -> -1 | I4: {=IFERROR(INDEX(_xlfn.SORTBY(_xlfn._xlws.FILTER('Standings Data'!$B$2:$M$49,'Standings Data'!$A$2:$A$49="A"),_xlfn._xlws.FILTER('Standings Data'!$K$2:$K$49,'Standings Data'!$A$2:$A$49="A"),1),2,9),"")} -> 4 | J4: {=IFERROR(INDEX(_xlfn.SORTBY(_xlfn._xlws.FILTER('Standings Data'!$B$2:$M$49,'Standings Data'!$A$2:$A$49="A"),_xlfn._xlws.FILTER('Standings Data'!$K$2:$K$49,'Standings Data'!$A$2:$A$49="A"),1),2,10),"")} -> 2 | K4: {=IFERROR(INDEX(_xlfn.SORTBY(_xlfn._xlws.FILTER('Standings Data'!$B$2:$M$49,'Standings Data'!$A$2:$A$49="A"),_xlfn._xlws.FILTER('Standings Data'!$K$2:$K$49,'Standings Data'!$A$2:$A$49="A"),1),2,11),"")} -> A2 | L4: {=IFERROR(INDEX(_xlfn.SORTBY(_xlfn._xlws.FILTER('Standings Data'!$B$2:$M$49,'Standings Data'!$A$2:$A$49="A"),_xlfn._xlws.FILTER('Standings Data'!$K$2:$K$49,'Standings Data'!$A$2:$A$49="A"),1),2,12),"")} -> Qualified | O4: {=IFERROR(INDEX(_xlfn.SORTBY(_xlfn._xlws.FILTER('Standings Data'!$B$2:$M$49,'Standings Data'!$A$2:$A$49="G"),_xlfn._xlws.FILTER('Standings Data'!$K$2:$K$49,'Standings Data'!$A$2:$A$49="G"),1),2,1),"")} -> Egypt | P4: {=IFERROR(INDEX(_xlfn.SORTBY(_xlfn._xlws.FILTER('Standings Data'!$B$2:$M$49,'Standings Data'!$A$2:$A$49="G"),_xlfn._xlws.FILTER('Standings Data'!$K$2:$K$49,'Standings Data'!$A$2:$A$49="G"),1),2,2),"")} -> 3 | Q4: {=IFERROR(INDEX(_xlfn.SORTBY(_xlfn._xlws.FILTER('Standings Data'!$B$2:$M$49,'Standings Data'!$A$2:$A$49="G"),_xlfn._xlws.FILTER('Standings Data'!$K$2:$K$49,'Standings Data'!$A$2:$A$49="G"),1),2,3),"")} -> 1 | R4: {=IFERROR(INDEX(_xlfn.SORTBY(_xlfn._xlws.FILTER('Standings Data'!$B$2:$M$49,'Standings Data'!$A$2:$A$49="G"),_xlfn._xlws.FILTER('Standings Data'!$K$2:$K$49,'Standings Data'!$A$2:$A$49="G"),1),2,4),"")} -> 2 | S4: {=IFERROR(INDEX(_xlfn.SORTBY(_xlfn._xlws.FILTER('Standings Data'!$B$2:$M$49,'Standings Data'!$A$2:$A$49="G"),_xlfn._xlws.FILTER('Standings Data'!$K$2:$K$49,'Standings Data'!$A$2:$A$49="G"),1),2,5),"")} -> 0 | T4: {=IFERROR(INDEX(_xlfn.SORTBY(_xlfn._xlws.FILTER('Standings Data'!$B$2:$M$49,'Standings Data'!$A$2:$A$49="G"),_xlfn._xlws.FILTER('Standings Data'!$K$2:$K$49,'Standings Data'!$A$2:$A$49="G"),1),2,6),"")} -> 5 | U4: {=IFERROR(INDEX(_xlfn.SORTBY(_xlfn._xlws.FILTER('Standings Data'!$B$2:$M$49,'Standings Data'!$A$2:$A$49="G"),_xlfn._xlws.FILTER('Standings Data'!$K$2:$K$49,'Standings Data'!$A$2:$A$49="G"),1),2,7),"")} -> 3 | V4: {=IFERROR(INDEX(_xlfn.SORTBY(_xlfn._xlws.FILTER('Standings Data'!$B$2:$M$49,'Standings Data'!$A$2:$A$49="G"),_xlfn._xlws.FILTER('Standings Data'!$K$2:$K$49,'Standings Data'!$A$2:$A$49="G"),1),2,8),"")} -> 2 | W4: {=IFERROR(INDEX(_xlfn.SORTBY(_xlfn._xlws.FILTER('Standings Data'!$B$2:$M$49,'Standings Data'!$A$2:$A$49="G"),_xlfn._xlws.FILTER('Standings Data'!$K$2:$K$49,'Standings Data'!$A$2:$A$49="G"),1),2,9),"")} -> 5 | X4: {=IFERROR(INDEX(_xlfn.SORTBY(_xlfn._xlws.FILTER('Standings Data'!$B$2:$M$49,'Standings Data'!$A$2:$A$49="G"),_xlfn._xlws.FILTER('Standings Data'!$K$2:$K$49,'Standings Data'!$A$2:$A$49="G"),1),2,10),"")} -> 2 | Y4: {=IFERROR(INDEX(_xlfn.SORTBY(_xlfn._xlws.FILTER('Standings Data'!$B$2:$M$49,'Standings Data'!$A$2:$A$49="G"),_xlfn._xlws.FILTER('Standings Data'!$K$2:$K$49,'Standings Data'!$A$2:$A$49="G"),1),2,11),"")} -> G2 | Z4: {=IFERROR(INDEX(_xlfn.SORTBY(_xlfn._xlws.FILTER('Standings Data'!$B$2:$M$49,'Standings Data'!$A$2:$A$49="G"),_xlfn._xlws.FILTER('Standings Data'!$K$2:$K$49,'Standings Data'!$A$2:$A$49="G"),1),2,12),"")} -> Qualified | AC4: ='Standings Data'!O3 -> 2 | AD4: ='Standings Data'!P3 -> Bosnia and Herzegovina | AE4: ='Standings Data'!Q3 -> B | AF4: ='Standings Data'!R3 -> 4 | AG4: ='Standings Data'!S3 -> -1 | AH4: ='Standings Data'!T3 -> 5 | AI4: ='Standings Data'!U3 -> Likely advances
A5: {=IFERROR(INDEX(_xlfn.SORTBY(_xlfn._xlws.FILTER('Standings Data'!$B$2:$M$49,'Standings Data'!$A$2:$A$49="A"),_xlfn._xlws.FILTER('Standings Data'!$K$2:$K$49,'Standings Data'!$A$2:$A$49="A"),1),3,1),"")} -> Korea Republic | B5: {=IFERROR(INDEX(_xlfn.SORTBY(_xlfn._xlws.FILTER('Standings Data'!$B$2:$M$49,'Standings Data'!$A$2:$A$49="A"),_xlfn._xlws.FILTER('Standings Data'!$K$2:$K$49,'Standings Data'!$A$2:$A$49="A"),1),3,2),"")} -> 3 | C5: {=IFERROR(INDEX(_xlfn.SORTBY(_xlfn._xlws.FILTER('Standings Data'!$B$2:$M$49,'Standings Data'!$A$2:$A$49="A"),_xlfn._xlws.FILTER('Standings Data'!$K$2:$K$49,'Standings Data'!$A$2:$A$49="A"),1),3,3),"")} -> 1 | D5: {=IFERROR(INDEX(_xlfn.SORTBY(_xlfn._xlws.FILTER('Standings Data'!$B$2:$M$49,'Standings Data'!$A$2:$A$49="A"),_xlfn._xlws.FILTER('Standings Data'!$K$2:$K$49,'Standings Data'!$A$2:$A$49="A"),1),3,4),"")} -> 0 | E5: {=IFERROR(INDEX(_xlfn.SORTBY(_xlfn._xlws.FILTER('Standings Data'!$B$2:$M$49,'Standings Data'!$A$2:$A$49="A"),_xlfn._xlws.FILTER('Standings Data'!$K$2:$K$49,'Standings Data'!$A$2:$A$49="A"),1),3,5),"")} -> 2 | F5: {=IFERROR(INDEX(_xlfn.SORTBY(_xlfn._xlws.FILTER('Standings Data'!$B$2:$M$49,'Standings Data'!$A$2:$A$49="A"),_xlfn._xlws.FILTER('Standings Data'!$K$2:$K$49,'Standings Data'!$A$2:$A$49="A"),1),3,6),"")} -> 2 | G5: {=IFERROR(INDEX(_xlfn.SORTBY(_xlfn._xlws.FILTER('Standings Data'!$B$2:$M$49,'Standings Data'!$A$2:$A$49="A"),_xlfn._xlws.FILTER('Standings Data'!$K$2:$K$49,'Standings Data'!$A$2:$A$49="A"),1),3,7),"")} -> 3 | H5: {=IFERROR(INDEX(_xlfn.SORTBY(_xlfn._xlws.FILTER('Standings Data'!$B$2:$M$49,'Standings Data'!$A$2:$A$49="A"),_xlfn._xlws.FILTER('Standings Data'!$K$2:$K$49,'Standings Data'!$A$2:$A$49="A"),1),3,8),"")} -> -1 | I5: {=IFERROR(INDEX(_xlfn.SORTBY(_xlfn._xlws.FILTER('Standings Data'!$B$2:$M$49,'Standings Data'!$A$2:$A$49="A"),_xlfn._xlws.FILTER('Standings Data'!$K$2:$K$49,'Standings Data'!$A$2:$A$49="A"),1),3,9),"")} -> 3 | J5: {=IFERROR(INDEX(_xlfn.SORTBY(_xlfn._xlws.FILTER('Standings Data'!$B$2:$M$49,'Standings Data'!$A$2:$A$49="A"),_xlfn._xlws.FILTER('Standings Data'!$K$2:$K$49,'Standings Data'!$A$2:$A$49="A"),1),3,10),"")} -> 3 | K5: {=IFERROR(INDEX(_xlfn.SORTBY(_xlfn._xlws.FILTER('Standings Data'!$B$2:$M$49,'Standings Data'!$A$2:$A$49="A"),_xlfn._xlws.FILTER('Standings Data'!$K$2:$K$49,'Standings Data'!$A$2:$A$49="A"),1),3,11),"")} -> A3 | L5: {=IFERROR(INDEX(_xlfn.SORTBY(_xlfn._xlws.FILTER('Standings Data'!$B$2:$M$49,'Standings Data'!$A$2:$A$49="A"),_xlfn._xlws.FILTER('Standings Data'!$K$2:$K$49,'Standings Data'!$A$2:$A$49="A"),1),3,12),"")} -> Third-place pool | O5: {=IFERROR(INDEX(_xlfn.SORTBY(_xlfn._xlws.FILTER('Standings Data'!$B$2:$M$49,'Standings Data'!$A$2:$A$49="G"),_xlfn._xlws.FILTER('Standings Data'!$K$2:$K$49,'Standings Data'!$A$2:$A$49="G"),1),3,1),"")} -> IR Iran | P5: {=IFERROR(INDEX(_xlfn.SORTBY(_xlfn._xlws.FILTER('Standings Data'!$B$2:$M$49,'Standings Data'!$A$2:$A$49="G"),_xlfn._xlws.FILTER('Standings Data'!$K$2:$K$49,'Standings Data'!$A$2:$A$49="G"),1),3,2),"")} -> 3 | Q5: {=IFERROR(INDEX(_xlfn.SORTBY(_xlfn._xlws.FILTER('Standings Data'!$B$2:$M$49,'Standings Data'!$A$2:$A$49="G"),_xlfn._xlws.FILTER('Standings Data'!$K$2:$K$49,'Standings Data'!$A$2:$A$49="G"),1),3,3),"")} -> 0 | R5: {=IFERROR(INDEX(_xlfn.SORTBY(_xlfn._xlws.FILTER('Standings Data'!$B$2:$M$49,'Standings Data'!$A$2:$A$49="G"),_xlfn._xlws.FILTER('Standings Data'!$K$2:$K$49,'Standings Data'!$A$2:$A$49="G"),1),3,4),"")} -> 3 | S5: {=IFERROR(INDEX(_xlfn.SORTBY(_xlfn._xlws.FILTER('Standings Data'!$B$2:$M$49,'Standings Data'!$A$2:$A$49="G"),_xlfn._xlws.FILTER('Standings Data'!$K$2:$K$49,'Standings Data'!$A$2:$A$49="G"),1),3,5),"")} -> 0 | T5: {=IFERROR(INDEX(_xlfn.SORTBY(_xlfn._xlws.FILTER('Standings Data'!$B$2:$M$49,'Standings Data'!$A$2:$A$49="G"),_xlfn._xlws.FILTER('Standings Data'!$K$2:$K$49,'Standings Data'!$A$2:$A$49="G"),1),3,6),"")} -> 3 | U5: {=IFERROR(INDEX(_xlfn.SORTBY(_xlfn._xlws.FILTER('Standings Data'!$B$2:$M$49,'Standings Data'!$A$2:$A$49="G"),_xlfn._xlws.FILTER('Standings Data'!$K$2:$K$49,'Standings Data'!$A$2:$A$49="G"),1),3,7),"")} -> 3 | V5: {=IFERROR(INDEX(_xlfn.SORTBY(_xlfn._xlws.FILTER('Standings Data'!$B$2:$M$49,'Standings Data'!$A$2:$A$49="G"),_xlfn._xlws.FILTER('Standings Data'!$K$2:$K$49,'Standings Data'!$A$2:$A$49="G"),1),3,8),"")} -> 0 | W5: {=IFERROR(INDEX(_xlfn.SORTBY(_xlfn._xlws.FILTER('Standings Data'!$B$2:$M$49,'Standings Data'!$A$2:$A$49="G"),_xlfn._xlws.FILTER('Standings Data'!$K$2:$K$49,'Standings Data'!$A$2:$A$49="G"),1),3,9),"")} -> 3 | X5: {=IFERROR(INDEX(_xlfn.SORTBY(_xlfn._xlws.FILTER('Standings Data'!$B$2:$M$49,'Standings Data'!$A$2:$A$49="G"),_xlfn._xlws.FILTER('Standings Data'!$K$2:$K$49,'Standings Data'!$A$2:$A$49="G"),1),3,10),"")} -> 3 | Y5: {=IFERROR(INDEX(_xlfn.SORTBY(_xlfn._xlws.FILTER('Standings Data'!$B$2:$M$49,'Standings Data'!$A$2:$A$49="G"),_xlfn._xlws.FILTER('Standings Data'!$K$2:$K$49,'Standings Data'!$A$2:$A$49="G"),1),3,11),"")} -> G3 | Z5: {=IFERROR(INDEX(_xlfn.SORTBY(_xlfn._xlws.FILTER('Standings Data'!$B$2:$M$49,'Standings Data'!$A$2:$A$49="G"),_xlfn._xlws.FILTER('Standings Data'!$K$2:$K$49,'Standings Data'!$A$2:$A$49="G"),1),3,12),"")} -> Third-place pool | AC5: ='Standings Data'!O4 -> 3 | AD5: ='Standings Data'!P4 -> Scotland | AE5: ='Standings Data'!Q4 -> C | AF5: ='Standings Data'!R4 -> 3 | AG5: ='Standings Data'!S4 -> -3 | AH5: ='Standings Data'!T4 -> 1 | AI5: ='Standings Data'!U4 -> Likely advances
A6: {=IFERROR(INDEX(_xlfn.SORTBY(_xlfn._xlws.FILTER('Standings Data'!$B$2:$M$49,'Standings Data'!$A$2:$A$49="A"),_xlfn._xlws.FILTER('Standings Data'!$K$2:$K$49,'Standings Data'!$A$2:$A$49="A"),1),4,1),"")} -> Czechia | B6: {=IFERROR(INDEX(_xlfn.SORTBY(_xlfn._xlws.FILTER('Standings Data'!$B$2:$M$49,'Standings Data'!$A$2:$A$49="A"),_xlfn._xlws.FILTER('Standings Data'!$K$2:$K$49,'Standings Data'!$A$2:$A$49="A"),1),4,2),"")} -> 3 | C6: {=IFERROR(INDEX(_xlfn.SORTBY(_xlfn._xlws.FILTER('Standings Data'!$B$2:$M$49,'Standings Data'!$A$2:$A$49="A"),_xlfn._xlws.FILTER('Standings Data'!$K$2:$K$49,'Standings Data'!$A$2:$A$49="A"),1),4,3),"")} -> 0 | D6: {=IFERROR(INDEX(_xlfn.SORTBY(_xlfn._xlws.FILTER('Standings Data'!$B$2:$M$49,'Standings Data'!$A$2:$A$49="A"),_xlfn._xlws.FILTER('Standings Data'!$K$2:$K$49,'Standings Data'!$A$2:$A$49="A"),1),4,4),"")} -> 1 | E6: {=IFERROR(INDEX(_xlfn.SORTBY(_xlfn._xlws.FILTER('Standings Data'!$B$2:$M$49,'Standings Data'!$A$2:$A$49="A"),_xlfn._xlws.FILTER('Standings Data'!$K$2:$K$49,'Standings Data'!$A$2:$A$49="A"),1),4,5),"")} -> 2 | F6: {=IFERROR(INDEX(_xlfn.SORTBY(_xlfn._xlws.FILTER('Standings Data'!$B$2:$M$49,'Standings Data'!$A$2:$A$49="A"),_xlfn._xlws.FILTER('Standings Data'!$K$2:$K$49,'Standings Data'!$A$2:$A$49="A"),1),4,6),"")} -> 2 | G6: {=IFERROR(INDEX(_xlfn.SORTBY(_xlfn._xlws.FILTER('Standings Data'!$B$2:$M$49,'Standings Data'!$A$2:$A$49="A"),_xlfn._xlws.FILTER('Standings Data'!$K$2:$K$49,'Standings Data'!$A$2:$A$49="A"),1),4,7),"")} -> 6 | H6: {=IFERROR(INDEX(_xlfn.SORTBY(_xlfn._xlws.FILTER('Standings Data'!$B$2:$M$49,'Standings Data'!$A$2:$A$49="A"),_xlfn._xlws.FILTER('Standings Data'!$K$2:$K$49,'Standings Data'!$A$2:$A$49="A"),1),4,8),"")} -> -4 | I6: {=IFERROR(INDEX(_xlfn.SORTBY(_xlfn._xlws.FILTER('Standings Data'!$B$2:$M$49,'Standings Data'!$A$2:$A$49="A"),_xlfn._xlws.FILTER('Standings Data'!$K$2:$K$49,'Standings Data'!$A$2:$A$49="A"),1),4,9),"")} -> 1 | J6: {=IFERROR(INDEX(_xlfn.SORTBY(_xlfn._xlws.FILTER('Standings Data'!$B$2:$M$49,'Standings Data'!$A$2:$A$49="A"),_xlfn._xlws.FILTER('Standings Data'!$K$2:$K$49,'Standings Data'!$A$2:$A$49="A"),1),4,10),"")} -> 4 | K6: {=IFERROR(INDEX(_xlfn.SORTBY(_xlfn._xlws.FILTER('Standings Data'!$B$2:$M$49,'Standings Data'!$A$2:$A$49="A"),_xlfn._xlws.FILTER('Standings Data'!$K$2:$K$49,'Standings Data'!$A$2:$A$49="A"),1),4,11),"")} -> A4 | L6: {=IFERROR(INDEX(_xlfn.SORTBY(_xlfn._xlws.FILTER('Standings Data'!$B$2:$M$49,'Standings Data'!$A$2:$A$49="A"),_xlfn._xlws.FILTER('Standings Data'!$K$2:$K$49,'Standings Data'!$A$2:$A$49="A"),1),4,12),"")} | O6: {=IFERROR(INDEX(_xlfn.SORTBY(_xlfn._xlws.FILTER('Standings Data'!$B$2:$M$49,'Standings Data'!$A$2:$A$49="G"),_xlfn._xlws.FILTER('Standings Data'!$K$2:$K$49,'Standings Data'!$A$2:$A$49="G"),1),4,1),"")} -> New Zealand | P6: {=IFERROR(INDEX(_xlfn.SORTBY(_xlfn._xlws.FILTER('Standings Data'!$B$2:$M$49,'Standings Data'!$A$2:$A$49="G"),_xlfn._xlws.FILTER('Standings Data'!$K$2:$K$49,'Standings Data'!$A$2:$A$49="G"),1),4,2),"")} -> 3 | Q6: {=IFERROR(INDEX(_xlfn.SORTBY(_xlfn._xlws.FILTER('Standings Data'!$B$2:$M$49,'Standings Data'!$A$2:$A$49="G"),_xlfn._xlws.FILTER('Standings Data'!$K$2:$K$49,'Standings Data'!$A$2:$A$49="G"),1),4,3),"")} -> 0 | R6: {=IFERROR(INDEX(_xlfn.SORTBY(_xlfn._xlws.FILTER('Standings Data'!$B$2:$M$49,'Standings Data'!$A$2:$A$49="G"),_xlfn._xlws.FILTER('Standings Data'!$K$2:$K$49,'Standings Data'!$A$2:$A$49="G"),1),4,4),"")} -> 1 | S6: {=IFERROR(INDEX(_xlfn.SORTBY(_xlfn._xlws.FILTER('Standings Data'!$B$2:$M$49,'Standings Data'!$A$2:$A$49="G"),_xlfn._xlws.FILTER('Standings Data'!$K$2:$K$49,'Standings Data'!$A$2:$A$49="G"),1),4,5),"")} -> 2 | T6: {=IFERROR(INDEX(_xlfn.SORTBY(_xlfn._xlws.FILTER('Standings Data'!$B$2:$M$49,'Standings Data'!$A$2:$A$49="G"),_xlfn._xlws.FILTER('Standings Data'!$K$2:$K$49,'Standings Data'!$A$2:$A$49="G"),1),4,6),"")} -> 4 | U6: {=IFERROR(INDEX(_xlfn.SORTBY(_xlfn._xlws.FILTER('Standings Data'!$B$2:$M$49,'Standings Data'!$A$2:$A$49="G"),_xlfn._xlws.FILTER('Standings Data'!$K$2:$K$49,'Standings Data'!$A$2:$A$49="G"),1),4,7),"")} -> 10 | V6: {=IFERROR(INDEX(_xlfn.SORTBY(_xlfn._xlws.FILTER('Standings Data'!$B$2:$M$49,'Standings Data'!$A$2:$A$49="G"),_xlfn._xlws.FILTER('Standings Data'!$K$2:$K$49,'Standings Data'!$A$2:$A$49="G"),1),4,8),"")} -> -6 | W6: {=IFERROR(INDEX(_xlfn.SORTBY(_xlfn._xlws.FILTER('Standings Data'!$B$2:$M$49,'Standings Data'!$A$2:$A$49="G"),_xlfn._xlws.FILTER('Standings Data'!$K$2:$K$49,'Standings Data'!$A$2:$A$49="G"),1),4,9),"")} -> 1 | X6: {=IFERROR(INDEX(_xlfn.SORTBY(_xlfn._xlws.FILTER('Standings Data'!$B$2:$M$49,'Standings Data'!$A$2:$A$49="G"),_xlfn._xlws.FILTER('Standings Data'!$K$2:$K$49,'Standings Data'!$A$2:$A$49="G"),1),4,10),"")} -> 4 | Y6: {=IFERROR(INDEX(_xlfn.SORTBY(_xlfn._xlws.FILTER('Standings Data'!$B$2:$M$49,'Standings Data'!$A$2:$A$49="G"),_xlfn._xlws.FILTER('Standings Data'!$K$2:$K$49,'Standings Data'!$A$2:$A$49="G"),1),4,11),"")} -> G4 | Z6: {=IFERROR(INDEX(_xlfn.SORTBY(_xlfn._xlws.FILTER('Standings Data'!$B$2:$M$49,'Standings Data'!$A$2:$A$49="G"),_xlfn._xlws.FILTER('Standings Data'!$K$2:$K$49,'Standings Data'!$A$2:$A$49="G"),1),4,12),"")} | AC6: ='Standings Data'!O5 -> 4 | AD6: ='Standings Data'!P5 -> Paraguay | AE6: ='Standings Data'!Q5 -> D | AF6: ='Standings Data'!R5 -> 4 | AG6: ='Standings Data'!S5 -> -2 | AH6: ='Standings Data'!T5 -> 2 | AI6: ='Standings Data'!U5 -> Likely advances
AC7: ='Standings Data'!O6 -> 5 | AD7: ='Standings Data'!P6 -> Ecuador | AE7: ='Standings Data'!Q6 -> E | AF7: ='Standings Data'!R6 -> 4 | AG7: ='Standings Data'!S6 -> 0 | AH7: ='Standings Data'!T6 -> 2 | AI7: ='Standings Data'!U6 -> Likely advances
A8: Group B standings | O8: Group H standings | AC8: ='Standings Data'!O7 -> 6 | AD8: ='Standings Data'!P7 -> Sweden | AE8: ='Standings Data'!Q7 -> F | AF8: ='Standings Data'!R7 -> 4 | AG8: ='Standings Data'!S7 -> 0 | AH8: ='Standings Data'!T7 -> 7 | AI8: ='Standings Data'!U7 -> Likely advances
A9: Team | B9: Pld | C9: W | D9: D | E9: L | F9: GF | G9: GA | H9: GD | I9: Pts | J9: Rank | K9: Position | L9: Advance Status | O9: Team | P9: Pld | Q9: W | R9: D | S9: L | T9: GF | U9: GA | V9: GD | W9: Pts | X9: Rank | Y9: Position | Z9: Advance Status | AC9: ='Standings Data'!O8 -> 7 | AD9: ='Standings Data'!P8 -> IR Iran | AE9: ='Standings Data'!Q8 -> G | AF9: ='Standings Data'!R8 -> 3 | AG9: ='Standings Data'!S8 -> 0 | AH9: ='Standings Data'!T8 -> 3 | AI9: ='Standings Data'!U8 -> Likely advances
A10: {=IFERROR(INDEX(_xlfn.SORTBY(_xlfn._xlws.FILTER('Standings Data'!$B$2:$M$49,'Standings Data'!$A$2:$A$49="B"),_xlfn._xlws.FILTER('Standings Data'!$K$2:$K$49,'Standings Data'!$A$2:$A$49="B"),1),1,1),"")} -> Switzerland | B10: {=IFERROR(INDEX(_xlfn.SORTBY(_xlfn._xlws.FILTER('Standings Data'!$B$2:$M$49,'Standings Data'!$A$2:$A$49="B"),_xlfn._xlws.FILTER('Standings Data'!$K$2:$K$49,'Standings Data'!$A$2:$A$49="B"),1),1,2),"")} -> 3 | C10: {=IFERROR(INDEX(_xlfn.SORTBY(_xlfn._xlws.FILTER('Standings Data'!$B$2:$M$49,'Standings Data'!$A$2:$A$49="B"),_xlfn._xlws.FILTER('Standings Data'!$K$2:$K$49,'Standings Data'!$A$2:$A$49="B"),1),1,3),"")} -> 2 | D10: {=IFERROR(INDEX(_xlfn.SORTBY(_xlfn._xlws.FILTER('Standings Data'!$B$2:$M$49,'Standings Data'!$A$2:$A$49="B"),_xlfn._xlws.FILTER('Standings Data'!$K$2:$K$49,'Standings Data'!$A$2:$A$49="B"),1),1,4),"")} -> 1 | E10: {=IFERROR(INDEX(_xlfn.SORTBY(_xlfn._xlws.FILTER('Standings Data'!$B$2:$M$49,'Standings Data'!$A$2:$A$49="B"),_xlfn._xlws.FILTER('Standings Data'!$K$2:$K$49,'Standings Data'!$A$2:$A$49="B"),1),1,5),"")} -> 0 | F10: {=IFERROR(INDEX(_xlfn.SORTBY(_xlfn._xlws.FILTER('Standings Data'!$B$2:$M$49,'Standings Data'!$A$2:$A$49="B"),_xlfn._xlws.FILTER('Standings Data'!$K$2:$K$49,'Standings Data'!$A$2:$A$49="B"),1),1,6),"")} -> 7 | G10: {=IFERROR(INDEX(_xlfn.SORTBY(_xlfn._xlws.FILTER('Standings Data'!$B$2:$M$49,'Standings Data'!$A$2:$A$49="B"),_xlfn._xlws.FILTER('Standings Data'!$K$2:$K$49,'Standings Data'!$A$2:$A$49="B"),1),1,7),"")} -> 3 | H10: {=IFERROR(INDEX(_xlfn.SORTBY(_xlfn._xlws.FILTER('Standings Data'!$B$2:$M$49,'Standings Data'!$A$2:$A$49="B"),_xlfn._xlws.FILTER('Standings Data'!$K$2:$K$49,'Standings Data'!$A$2:$A$49="B"),1),1,8),"")} -> 4 | I10: {=IFERROR(INDEX(_xlfn.SORTBY(_xlfn._xlws.FILTER('Standings Data'!$B$2:$M$49,'Standings Data'!$A$2:$A$49="B"),_xlfn._xlws.FILTER('Standings Data'!$K$2:$K$49,'Standings Data'!$A$2:$A$49="B"),1),1,9),"")} -> 7 | J10: {=IFERROR(INDEX(_xlfn.SORTBY(_xlfn._xlws.FILTER('Standings Data'!$B$2:$M$49,'Standings Data'!$A$2:$A$49="B"),_xlfn._xlws.FILTER('Standings Data'!$K$2:$K$49,'Standings Data'!$A$2:$A$49="B"),1),1,10),"")} -> 1 | K10: {=IFERROR(INDEX(_xlfn.SORTBY(_xlfn._xlws.FILTER('Standings Data'!$B$2:$M$49,'Standings Data'!$A$2:$A$49="B"),_xlfn._xlws.FILTER('Standings Data'!$K$2:$K$49,'Standings Data'!$A$2:$A$49="B"),1),1,11),"")} -> B1 | L10: {=IFERROR(INDEX(_xlfn.SORTBY(_xlfn._xlws.FILTER('Standings Data'!$B$2:$M$49,'Standings Data'!$A$2:$A$49="B"),_xlfn._xlws.FILTER('Standings Data'!$K$2:$K$49,'Standings Data'!$A$2:$A$49="B"),1),1,12),"")} -> Qualified | O10: {=IFERROR(INDEX(_xlfn.SORTBY(_xlfn._xlws.FILTER('Standings Data'!$B$2:$M$49,'Standings Data'!$A$2:$A$49="H"),_xlfn._xlws.FILTER('Standings Data'!$K$2:$K$49,'Standings Data'!$A$2:$A$49="H"),1),1,1),"")} -> Spain | P10: {=IFERROR(INDEX(_xlfn.SORTBY(_xlfn._xlws.FILTER('Standings Data'!$B$2:$M$49,'Standings Data'!$A$2:$A$49="H"),_xlfn._xlws.FILTER('Standings Data'!$K$2:$K$49,'Standings Data'!$A$2:$A$49="H"),1),1,2),"")} -> 3 | Q10: {=IFERROR(INDEX(_xlfn.SORTBY(_xlfn._xlws.FILTER('Standings Data'!$B$2:$M$49,'Standings Data'!$A$2:$A$49="H"),_xlfn._xlws.FILTER('Standings Data'!$K$2:$K$49,'Standings Data'!$A$2:$A$49="H"),1),1,3),"")} -> 2 | R10: {=IFERROR(INDEX(_xlfn.SORTBY(_xlfn._xlws.FILTER('Standings Data'!$B$2:$M$49,'Standings Data'!$A$2:$A$49="H"),_xlfn._xlws.FILTER('Standings Data'!$K$2:$K$49,'Standings Data'!$A$2:$A$49="H"),1),1,4),"")} -> 1 | S10: {=IFERROR(INDEX(_xlfn.SORTBY(_xlfn._xlws.FILTER('Standings Data'!$B$2:$M$49,'Standings Data'!$A$2:$A$49="H"),_xlfn._xlws.FILTER('Standings Data'!$K$2:$K$49,'Standings Data'!$A$2:$A$49="H"),1),1,5),"")} -> 0 | T10: {=IFERROR(INDEX(_xlfn.SORTBY(_xlfn._xlws.FILTER('Standings Data'!$B$2:$M$49,'Standings Data'!$A$2:$A$49="H"),_xlfn._xlws.FILTER('Standings Data'!$K$2:$K$49,'Standings Data'!$A$2:$A$49="H"),1),1,6),"")} -> 5 | U10: {=IFERROR(INDEX(_xlfn.SORTBY(_xlfn._xlws.FILTER('Standings Data'!$B$2:$M$49,'Standings Data'!$A$2:$A$49="H"),_xlfn._xlws.FILTER('Standings Data'!$K$2:$K$49,'Standings Data'!$A$2:$A$49="H"),1),1,7),"")} -> 0 | V10: {=IFERROR(INDEX(_xlfn.SORTBY(_xlfn._xlws.FILTER('Standings Data'!$B$2:$M$49,'Standings Data'!$A$2:$A$49="H"),_xlfn._xlws.FILTER('Standings Data'!$K$2:$K$49,'Standings Data'!$A$2:$A$49="H"),1),1,8),"")} -> 5 | W10: {=IFERROR(INDEX(_xlfn.SORTBY(_xlfn._xlws.FILTER('Standings Data'!$B$2:$M$49,'Standings Data'!$A$2:$A$49="H"),_xlfn._xlws.FILTER('Standings Data'!$K$2:$K$49,'Standings Data'!$A$2:$A$49="H"),1),1,9),"")} -> 7 | X10: {=IFERROR(INDEX(_xlfn.SORTBY(_xlfn._xlws.FILTER('Standings Data'!$B$2:$M$49,'Standings Data'!$A$2:$A$49="H"),_xlfn._xlws.FILTER('Standings Data'!$K$2:$K$49,'Standings Data'!$A$2:$A$49="H"),1),1,10),"")} -> 1 | Y10: {=IFERROR(INDEX(_xlfn.SORTBY(_xlfn._xlws.FILTER('Standings Data'!$B$2:$M$49,'Standings Data'!$A$2:$A$49="H"),_xlfn._xlws.FILTER('Standings Data'!$K$2:$K$49,'Standings Data'!$A$2:$A$49="H"),1),1,11),"")} -> H1 | Z10: {=IFERROR(INDEX(_xlfn.SORTBY(_xlfn._xlws.FILTER('Standings Data'!$B$2:$M$49,'Standings Data'!$A$2:$A$49="H"),_xlfn._xlws.FILTER('Standings Data'!$K$2:$K$49,'Standings Data'!$A$2:$A$49="H"),1),1,12),"")} -> Qualified | AC10: ='Standings Data'!O9 -> 8 | AD10: ='Standings Data'!P9 -> Uruguay | AE10: ='Standings Data'!Q9 -> H | AF10: ='Standings Data'!R9 -> 2 | AG10: ='Standings Data'!S9 -> -1 | AH10: ='Standings Data'!T9 -> 3 | AI10: ='Standings Data'!U9 -> Watch
A11: {=IFERROR(INDEX(_xlfn.SORTBY(_xlfn._xlws.FILTER('Standings Data'!$B$2:$M$49,'Standings Data'!$A$2:$A$49="B"),_xlfn._xlws.FILTER('Standings Data'!$K$2:$K$49,'Standings Data'!$A$2:$A$49="B"),1),2,1),"")} -> Canada | B11: {=IFERROR(INDEX(_xlfn.SORTBY(_xlfn._xlws.FILTER('Standings Data'!$B$2:$M$49,'Standings Data'!$A$2:$A$49="B"),_xlfn._xlws.FILTER('Standings Data'!$K$2:$K$49,'Standings Data'!$A$2:$A$49="B"),1),2,2),"")} -> 3 | C11: {=IFERROR(INDEX(_xlfn.SORTBY(_xlfn._xlws.FILTER('Standings Data'!$B$2:$M$49,'Standings Data'!$A$2:$A$49="B"),_xlfn._xlws.FILTER('Standings Data'!$K$2:$K$49,'Standings Data'!$A$2:$A$49="B"),1),2,3),"")} -> 1 | D11: {=IFERROR(INDEX(_xlfn.SORTBY(_xlfn._xlws.FILTER('Standings Data'!$B$2:$M$49,'Standings Data'!$A$2:$A$49="B"),_xlfn._xlws.FILTER('Standings Data'!$K$2:$K$49,'Standings Data'!$A$2:$A$49="B"),1),2,4),"")} -> 1 | E11: {=IFERROR(INDEX(_xlfn.SORTBY(_xlfn._xlws.FILTER('Standings Data'!$B$2:$M$49,'Standings Data'!$A$2:$A$49="B"),_xlfn._xlws.FILTER('Standings Data'!$K$2:$K$49,'Standings Data'!$A$2:$A$49="B"),1),2,5),"")} -> 1 | F11: {=IFERROR(INDEX(_xlfn.SORTBY(_xlfn._xlws.FILTER('Standings Data'!$B$2:$M$49,'Standings Data'!$A$2:$A$49="B"),_xlfn._xlws.FILTER('Standings Data'!$K$2:$K$49,'Standings Data'!$A$2:$A$49="B"),1),2,6),"")} -> 8 | G11: {=IFERROR(INDEX(_xlfn.SORTBY(_xlfn._xlws.FILTER('Standings Data'!$B$2:$M$49,'Standings Data'!$A$2:$A$49="B"),_xlfn._xlws.FILTER('Standings Data'!$K$2:$K$49,'Standings Data'!$A$2:$A$49="B"),1),2,7),"")} -> 3 | H11: {=IFERROR(INDEX(_xlfn.SORTBY(_xlfn._xlws.FILTER('Standings Data'!$B$2:$M$49,'Standings Data'!$A$2:$A$49="B"),_xlfn._xlws.FILTER('Standings Data'!$K$2:$K$49,'Standings Data'!$A$2:$A$49="B"),1),2,8),"")} -> 5 | I11: {=IFERROR(INDEX(_xlfn.SORTBY(_xlfn._xlws.FILTER('Standings Data'!$B$2:$M$49,'Standings Data'!$A$2:$A$49="B"),_xlfn._xlws.FILTER('Standings Data'!$K$2:$K$49,'Standings Data'!$A$2:$A$49="B"),1),2,9),"")} -> 4 | J11: {=IFERROR(INDEX(_xlfn.SORTBY(_xlfn._xlws.FILTER('Standings Data'!$B$2:$M$49,'Standings Data'!$A$2:$A$49="B"),_xlfn._xlws.FILTER('Standings Data'!$K$2:$K$49,'Standings Data'!$A$2:$A$49="B"),1),2,10),"")} -> 2 | K11: {=IFERROR(INDEX(_xlfn.SORTBY(_xlfn._xlws.FILTER('Standings Data'!$B$2:$M$49,'Standings Data'!$A$2:$A$49="B"),_xlfn._xlws.FILTER('Standings Data'!$K$2:$K$49,'Standings Data'!$A$2:$A$49="B"),1),2,11),"")} -> B2 | L11: {=IFERROR(INDEX(_xlfn.SORTBY(_xlfn._xlws.FILTER('Standings Data'!$B$2:$M$49,'Standings Data'!$A$2:$A$49="B"),_xlfn._xlws.FILTER('Standings Data'!$K$2:$K$49,'Standings Data'!$A$2:$A$49="B"),1),2,12),"")} -> Qualified | O11: {=IFERROR(INDEX(_xlfn.SORTBY(_xlfn._xlws.FILTER('Standings Data'!$B$2:$M$49,'Standings Data'!$A$2:$A$49="H"),_xlfn._xlws.FILTER('Standings Data'!$K$2:$K$49,'Standings Data'!$A$2:$A$49="H"),1),2,1),"")} -> Cabo Verde | P11: {=IFERROR(INDEX(_xlfn.SORTBY(_xlfn._xlws.FILTER('Standings Data'!$B$2:$M$49,'Standings Data'!$A$2:$A$49="H"),_xlfn._xlws.FILTER('Standings Data'!$K$2:$K$49,'Standings Data'!$A$2:$A$49="H"),1),2,2),"")} -> 3 | Q11: {=IFERROR(INDEX(_xlfn.SORTBY(_xlfn._xlws.FILTER('Standings Data'!$B$2:$M$49,'Standings Data'!$A$2:$A$49="H"),_xlfn._xlws.FILTER('Standings Data'!$K$2:$K$49,'Standings Data'!$A$2:$A$49="H"),1),2,3),"")} -> 0 | R11: {=IFERROR(INDEX(_xlfn.SORTBY(_xlfn._xlws.FILTER('Standings Data'!$B$2:$M$49,'Standings Data'!$A$2:$A$49="H"),_xlfn._xlws.FILTER('Standings Data'!$K$2:$K$49,'Standings Data'!$A$2:$A$49="H"),1),2,4),"")} -> 3 | S11: {=IFERROR(INDEX(_xlfn.SORTBY(_xlfn._xlws.FILTER('Standings Data'!$B$2:$M$49,'Standings Data'!$A$2:$A$49="H"),_xlfn._xlws.FILTER('Standings Data'!$K$2:$K$49,'Standings Data'!$A$2:$A$49="H"),1),2,5),"")} -> 0 | T11: {=IFERROR(INDEX(_xlfn.SORTBY(_xlfn._xlws.FILTER('Standings Data'!$B$2:$M$49,'Standings Data'!$A$2:$A$49="H"),_xlfn._xlws.FILTER('Standings Data'!$K$2:$K$49,'Standings Data'!$A$2:$A$49="H"),1),2,6),"")} -> 2 | U11: {=IFERROR(INDEX(_xlfn.SORTBY(_xlfn._xlws.FILTER('Standings Data'!$B$2:$M$49,'Standings Data'!$A$2:$A$49="H"),_xlfn._xlws.FILTER('Standings Data'!$K$2:$K$49,'Standings Data'!$A$2:$A$49="H"),1),2,7),"")} -> 2 | V11: {=IFERROR(INDEX(_xlfn.SORTBY(_xlfn._xlws.FILTER('Standings Data'!$B$2:$M$49,'Standings Data'!$A$2:$A$49="H"),_xlfn._xlws.FILTER('Standings Data'!$K$2:$K$49,'Standings Data'!$A$2:$A$49="H"),1),2,8),"")} -> 0 | W11: {=IFERROR(INDEX(_xlfn.SORTBY(_xlfn._xlws.FILTER('Standings Data'!$B$2:$M$49,'Standings Data'!$A$2:$A$49="H"),_xlfn._xlws.FILTER('Standings Data'!$K$2:$K$49,'Standings Data'!$A$2:$A$49="H"),1),2,9),"")} -> 3 | X11: {=IFERROR(INDEX(_xlfn.SORTBY(_xlfn._xlws.FILTER('Standings Data'!$B$2:$M$49,'Standings Data'!$A$2:$A$49="H"),_xlfn._xlws.FILTER('Standings Data'!$K$2:$K$49,'Standings Data'!$A$2:$A$49="H"),1),2,10),"")} -> 2 | Y11: {=IFERROR(INDEX(_xlfn.SORTBY(_xlfn._xlws.FILTER('Standings Data'!$B$2:$M$49,'Standings Data'!$A$2:$A$49="H"),_xlfn._xlws.FILTER('Standings Data'!$K$2:$K$49,'Standings Data'!$A$2:$A$49="H"),1),2,11),"")} -> H2 | Z11: {=IFERROR(INDEX(_xlfn.SORTBY(_xlfn._xlws.FILTER('Standings Data'!$B$2:$M$49,'Standings Data'!$A$2:$A$49="H"),_xlfn._xlws.FILTER('Standings Data'!$K$2:$K$49,'Standings Data'!$A$2:$A$49="H"),1),2,12),"")} -> Qualified | AC11: ='Standings Data'!O10 -> 9 | AD11: ='Standings Data'!P10 -> Senegal | AE11: ='Standings Data'!Q10 -> I | AF11: ='Standings Data'!R10 -> 3 | AG11: ='Standings Data'!S10 -> 2 | AH11: ='Standings Data'!T10 -> 8 | AI11: ='Standings Data'!U10 -> Likely advances
A12: {=IFERROR(INDEX(_xlfn.SORTBY(_xlfn._xlws.FILTER('Standings Data'!$B$2:$M$49,'Standings Data'!$A$2:$A$49="B"),_xlfn._xlws.FILTER('Standings Data'!$K$2:$K$49,'Standings Data'!$A$2:$A$49="B"),1),3,1),"")} -> Bosnia and Herzegovina | B12: {=IFERROR(INDEX(_xlfn.SORTBY(_xlfn._xlws.FILTER('Standings Data'!$B$2:$M$49,'Standings Data'!$A$2:$A$49="B"),_xlfn._xlws.FILTER('Standings Data'!$K$2:$K$49,'Standings Data'!$A$2:$A$49="B"),1),3,2),"")} -> 3 | C12: {=IFERROR(INDEX(_xlfn.SORTBY(_xlfn._xlws.FILTER('Standings Data'!$B$2:$M$49,'Standings Data'!$A$2:$A$49="B"),_xlfn._xlws.FILTER('Standings Data'!$K$2:$K$49,'Standings Data'!$A$2:$A$49="B"),1),3,3),"")} -> 1 | D12: {=IFERROR(INDEX(_xlfn.SORTBY(_xlfn._xlws.FILTER('Standings Data'!$B$2:$M$49,'Standings Data'!$A$2:$A$49="B"),_xlfn._xlws.FILTER('Standings Data'!$K$2:$K$49,'Standings Data'!$A$2:$A$49="B"),1),3,4),"")} -> 1 | E12: {=IFERROR(INDEX(_xlfn.SORTBY(_xlfn._xlws.FILTER('Standings Data'!$B$2:$M$49,'Standings Data'!$A$2:$A$49="B"),_xlfn._xlws.FILTER('Standings Data'!$K$2:$K$49,'Standings Data'!$A$2:$A$49="B"),1),3,5),"")} -> 1 | F12: {=IFERROR(INDEX(_xlfn.SORTBY(_xlfn._xlws.FILTER('Standings Data'!$B$2:$M$49,'Standings Data'!$A$2:$A$49="B"),_xlfn._xlws.FILTER('Standings Data'!$K$2:$K$49,'Standings Data'!$A$2:$A$49="B"),1),3,6),"")} -> 5 | G12: {=IFERROR(INDEX(_xlfn.SORTBY(_xlfn._xlws.FILTER('Standings Data'!$B$2:$M$49,'Standings Data'!$A$2:$A$49="B"),_xlfn._xlws.FILTER('Standings Data'!$K$2:$K$49,'Standings Data'!$A$2:$A$49="B"),1),3,7),"")} -> 6 | H12: {=IFERROR(INDEX(_xlfn.SORTBY(_xlfn._xlws.FILTER('Standings Data'!$B$2:$M$49,'Standings Data'!$A$2:$A$49="B"),_xlfn._xlws.FILTER('Standings Data'!$K$2:$K$49,'Standings Data'!$A$2:$A$49="B"),1),3,8),"")} -> -1 | I12: {=IFERROR(INDEX(_xlfn.SORTBY(_xlfn._xlws.FILTER('Standings Data'!$B$2:$M$49,'Standings Data'!$A$2:$A$49="B"),_xlfn._xlws.FILTER('Standings Data'!$K$2:$K$49,'Standings Data'!$A$2:$A$49="B"),1),3,9),"")} -> 4 | J12: {=IFERROR(INDEX(_xlfn.SORTBY(_xlfn._xlws.FILTER('Standings Data'!$B$2:$M$49,'Standings Data'!$A$2:$A$49="B"),_xlfn._xlws.FILTER('Standings Data'!$K$2:$K$49,'Standings Data'!$A$2:$A$49="B"),1),3,10),"")} -> 3 | K12: {=IFERROR(INDEX(_xlfn.SORTBY(_xlfn._xlws.FILTER('Standings Data'!$B$2:$M$49,'Standings Data'!$A$2:$A$49="B"),_xlfn._xlws.FILTER('Standings Data'!$K$2:$K$49,'Standings Data'!$A$2:$A$49="B"),1),3,11),"")} -> B3 | L12: {=IFERROR(INDEX(_xlfn.SORTBY(_xlfn._xlws.FILTER('Standings Data'!$B$2:$M$49,'Standings Data'!$A$2:$A$49="B"),_xlfn._xlws.FILTER('Standings Data'!$K$2:$K$49,'Standings Data'!$A$2:$A$49="B"),1),3,12),"")} -> Third-place pool | O12: {=IFERROR(INDEX(_xlfn.SORTBY(_xlfn._xlws.FILTER('Standings Data'!$B$2:$M$49,'Standings Data'!$A$2:$A$49="H"),_xlfn._xlws.FILTER('Standings Data'!$K$2:$K$49,'Standings Data'!$A$2:$A$49="H"),1),3,1),"")} -> Uruguay | P12: {=IFERROR(INDEX(_xlfn.SORTBY(_xlfn._xlws.FILTER('Standings Data'!$B$2:$M$49,'Standings Data'!$A$2:$A$49="H"),_xlfn._xlws.FILTER('Standings Data'!$K$2:$K$49,'Standings Data'!$A$2:$A$49="H"),1),3,2),"")} -> 3 | Q12: {=IFERROR(INDEX(_xlfn.SORTBY(_xlfn._xlws.FILTER('Standings Data'!$B$2:$M$49,'Standings Data'!$A$2:$A$49="H"),_xlfn._xlws.FILTER('Standings Data'!$K$2:$K$49,'Standings Data'!$A$2:$A$49="H"),1),3,3),"")} -> 0 | R12: {=IFERROR(INDEX(_xlfn.SORTBY(_xlfn._xlws.FILTER('Standings Data'!$B$2:$M$49,'Standings Data'!$A$2:$A$49="H"),_xlfn._xlws.FILTER('Standings Data'!$K$2:$K$49,'Standings Data'!$A$2:$A$49="H"),1),3,4),"")} -> 2 | S12: {=IFERROR(INDEX(_xlfn.SORTBY(_xlfn._xlws.FILTER('Standings Data'!$B$2:$M$49,'Standings Data'!$A$2:$A$49="H"),_xlfn._xlws.FILTER('Standings Data'!$K$2:$K$49,'Standings Data'!$A$2:$A$49="H"),1),3,5),"")} -> 1 | T12: {=IFERROR(INDEX(_xlfn.SORTBY(_xlfn._xlws.FILTER('Standings Data'!$B$2:$M$49,'Standings Data'!$A$2:$A$49="H"),_xlfn._xlws.FILTER('Standings Data'!$K$2:$K$49,'Standings Data'!$A$2:$A$49="H"),1),3,6),"")} -> 3 | U12: {=IFERROR(INDEX(_xlfn.SORTBY(_xlfn._xlws.FILTER('Standings Data'!$B$2:$M$49,'Standings Data'!$A$2:$A$49="H"),_xlfn._xlws.FILTER('Standings Data'!$K$2:$K$49,'Standings Data'!$A$2:$A$49="H"),1),3,7),"")} -> 4 | V12: {=IFERROR(INDEX(_xlfn.SORTBY(_xlfn._xlws.FILTER('Standings Data'!$B$2:$M$49,'Standings Data'!$A$2:$A$49="H"),_xlfn._xlws.FILTER('Standings Data'!$K$2:$K$49,'Standings Data'!$A$2:$A$49="H"),1),3,8),"")} -> -1 | W12: {=IFERROR(INDEX(_xlfn.SORTBY(_xlfn._xlws.FILTER('Standings Data'!$B$2:$M$49,'Standings Data'!$A$2:$A$49="H"),_xlfn._xlws.FILTER('Standings Data'!$K$2:$K$49,'Standings Data'!$A$2:$A$49="H"),1),3,9),"")} -> 2 | X12: {=IFERROR(INDEX(_xlfn.SORTBY(_xlfn._xlws.FILTER('Standings Data'!$B$2:$M$49,'Standings Data'!$A$2:$A$49="H"),_xlfn._xlws.FILTER('Standings Data'!$K$2:$K$49,'Standings Data'!$A$2:$A$49="H"),1),3,10),"")} -> 3 | Y12: {=IFERROR(INDEX(_xlfn.SORTBY(_xlfn._xlws.FILTER('Standings Data'!$B$2:$M$49,'Standings Data'!$A$2:$A$49="H"),_xlfn._xlws.FILTER('Standings Data'!$K$2:$K$49,'Standings Data'!$A$2:$A$49="H"),1),3,11),"")} -> H3 | Z12: {=IFERROR(INDEX(_xlfn.SORTBY(_xlfn._xlws.FILTER('Standings Data'!$B$2:$M$49,'Standings Data'!$A$2:$A$49="H"),_xlfn._xlws.FILTER('Standings Data'!$K$2:$K$49,'Standings Data'!$A$2:$A$49="H"),1),3,12),"")} -> Third-place pool | AC12: ='Standings Data'!O11 -> 10 | AD12: ='Standings Data'!P11 -> Algeria | AE12: ='Standings Data'!Q11 -> J | AF12: ='Standings Data'!R11 -> 4 | AG12: ='Standings Data'!S11 -> -2 | AH12: ='Standings Data'!T11 -> 5 | AI12: ='Standings Data'!U11 -> Likely advances
A13: {=IFERROR(INDEX(_xlfn.SORTBY(_xlfn._xlws.FILTER('Standings Data'!$B$2:$M$49,'Standings Data'!$A$2:$A$49="B"),_xlfn._xlws.FILTER('Standings Data'!$K$2:$K$49,'Standings Data'!$A$2:$A$49="B"),1),4,1),"")} -> Qatar | B13: {=IFERROR(INDEX(_xlfn.SORTBY(_xlfn._xlws.FILTER('Standings Data'!$B$2:$M$49,'Standings Data'!$A$2:$A$49="B"),_xlfn._xlws.FILTER('Standings Data'!$K$2:$K$49,'Standings Data'!$A$2:$A$49="B"),1),4,2),"")} -> 3 | C13: {=IFERROR(INDEX(_xlfn.SORTBY(_xlfn._xlws.FILTER('Standings Data'!$B$2:$M$49,'Standings Data'!$A$2:$A$49="B"),_xlfn._xlws.FILTER('Standings Data'!$K$2:$K$49,'Standings Data'!$A$2:$A$49="B"),1),4,3),"")} -> 0 | D13: {=IFERROR(INDEX(_xlfn.SORTBY(_xlfn._xlws.FILTER('Standings Data'!$B$2:$M$49,'Standings Data'!$A$2:$A$49="B"),_xlfn._xlws.FILTER('Standings Data'!$K$2:$K$49,'Standings Data'!$A$2:$A$49="B"),1),4,4),"")} -> 1 | E13: {=IFERROR(INDEX(_xlfn.SORTBY(_xlfn._xlws.FILTER('Standings Data'!$B$2:$M$49,'Standings Data'!$A$2:$A$49="B"),_xlfn._xlws.FILTER('Standings Data'!$K$2:$K$49,'Standings Data'!$A$2:$A$49="B"),1),4,5),"")} -> 2 | F13: {=IFERROR(INDEX(_xlfn.SORTBY(_xlfn._xlws.FILTER('Standings Data'!$B$2:$M$49,'Standings Data'!$A$2:$A$49="B"),_xlfn._xlws.FILTER('Standings Data'!$K$2:$K$49,'Standings Data'!$A$2:$A$49="B"),1),4,6),"")} -> 2 | G13: {=IFERROR(INDEX(_xlfn.SORTBY(_xlfn._xlws.FILTER('Standings Data'!$B$2:$M$49,'Standings Data'!$A$2:$A$49="B"),_xlfn._xlws.FILTER('Standings Data'!$K$2:$K$49,'Standings Data'!$A$2:$A$49="B"),1),4,7),"")} -> 10 | H13: {=IFERROR(INDEX(_xlfn.SORTBY(_xlfn._xlws.FILTER('Standings Data'!$B$2:$M$49,'Standings Data'!$A$2:$A$49="B"),_xlfn._xlws.FILTER('Standings Data'!$K$2:$K$49,'Standings Data'!$A$2:$A$49="B"),1),4,8),"")} -> -8 | I13: {=IFERROR(INDEX(_xlfn.SORTBY(_xlfn._xlws.FILTER('Standings Data'!$B$2:$M$49,'Standings Data'!$A$2:$A$49="B"),_xlfn._xlws.FILTER('Standings Data'!$K$2:$K$49,'Standings Data'!$A$2:$A$49="B"),1),4,9),"")} -> 1 | J13: {=IFERROR(INDEX(_xlfn.SORTBY(_xlfn._xlws.FILTER('Standings Data'!$B$2:$M$49,'Standings Data'!$A$2:$A$49="B"),_xlfn._xlws.FILTER('Standings Data'!$K$2:$K$49,'Standings Data'!$A$2:$A$49="B"),1),4,10),"")} -> 4 | K13: {=IFERROR(INDEX(_xlfn.SORTBY(_xlfn._xlws.FILTER('Standings Data'!$B$2:$M$49,'Standings Data'!$A$2:$A$49="B"),_xlfn._xlws.FILTER('Standings Data'!$K$2:$K$49,'Standings Data'!$A$2:$A$49="B"),1),4,11),"")} -> B4 | L13: {=IFERROR(INDEX(_xlfn.SORTBY(_xlfn._xlws.FILTER('Standings Data'!$B$2:$M$49,'Standings Data'!$A$2:$A$49="B"),_xlfn._xlws.FILTER('Standings Data'!$K$2:$K$49,'Standings Data'!$A$2:$A$49="B"),1),4,12),"")} | O13: {=IFERROR(INDEX(_xlfn.SORTBY(_xlfn._xlws.FILTER('Standings Data'!$B$2:$M$49,'Standings Data'!$A$2:$A$49="H"),_xlfn._xlws.FILTER('Standings Data'!$K$2:$K$49,'Standings Data'!$A$2:$A$49="H"),1),4,1),"")} -> Saudi Arabia | P13: {=IFERROR(INDEX(_xlfn.SORTBY(_xlfn._xlws.FILTER('Standings Data'!$B$2:$M$49,'Standings Data'!$A$2:$A$49="H"),_xlfn._xlws.FILTER('Standings Data'!$K$2:$K$49,'Standings Data'!$A$2:$A$49="H"),1),4,2),"")} -> 3 | Q13: {=IFERROR(INDEX(_xlfn.SORTBY(_xlfn._xlws.FILTER('Standings Data'!$B$2:$M$49,'Standings Data'!$A$2:$A$49="H"),_xlfn._xlws.FILTER('Standings Data'!$K$2:$K$49,'Standings Data'!$A$2:$A$49="H"),1),4,3),"")} -> 0 | R13: {=IFERROR(INDEX(_xlfn.SORTBY(_xlfn._xlws.FILTER('Standings Data'!$B$2:$M$49,'Standings Data'!$A$2:$A$49="H"),_xlfn._xlws.FILTER('Standings Data'!$K$2:$K$49,'Standings Data'!$A$2:$A$49="H"),1),4,4),"")} -> 2 | S13: {=IFERROR(INDEX(_xlfn.SORTBY(_xlfn._xlws.FILTER('Standings Data'!$B$2:$M$49,'Standings Data'!$A$2:$A$49="H"),_xlfn._xlws.FILTER('Standings Data'!$K$2:$K$49,'Standings Data'!$A$2:$A$49="H"),1),4,5),"")} -> 1 | T13: {=IFERROR(INDEX(_xlfn.SORTBY(_xlfn._xlws.FILTER('Standings Data'!$B$2:$M$49,'Standings Data'!$A$2:$A$49="H"),_xlfn._xlws.FILTER('Standings Data'!$K$2:$K$49,'Standings Data'!$A$2:$A$49="H"),1),4,6),"")} -> 1 | U13: {=IFERROR(INDEX(_xlfn.SORTBY(_xlfn._xlws.FILTER('Standings Data'!$B$2:$M$49,'Standings Data'!$A$2:$A$49="H"),_xlfn._xlws.FILTER('Standings Data'!$K$2:$K$49,'Standings Data'!$A$2:$A$49="H"),1),4,7),"")} -> 5 | V13: {=IFERROR(INDEX(_xlfn.SORTBY(_xlfn._xlws.FILTER('Standings Data'!$B$2:$M$49,'Standings Data'!$A$2:$A$49="H"),_xlfn._xlws.FILTER('Standings Data'!$K$2:$K$49,'Standings Data'!$A$2:$A$49="H"),1),4,8),"")} -> -4 | W13: {=IFERROR(INDEX(_xlfn.SORTBY(_xlfn._xlws.FILTER('Standings Data'!$B$2:$M$49,'Standings Data'!$A$2:$A$49="H"),_xlfn._xlws.FILTER('Standings Data'!$K$2:$K$49,'Standings Data'!$A$2:$A$49="H"),1),4,9),"")} -> 2 | X13: {=IFERROR(INDEX(_xlfn.SORTBY(_xlfn._xlws.FILTER('Standings Data'!$B$2:$M$49,'Standings Data'!$A$2:$A$49="H"),_xlfn._xlws.FILTER('Standings Data'!$K$2:$K$49,'Standings Data'!$A$2:$A$49="H"),1),4,10),"")} -> 4 | Y13: {=IFERROR(INDEX(_xlfn.SORTBY(_xlfn._xlws.FILTER('Standings Data'!$B$2:$M$49,'Standings Data'!$A$2:$A$49="H"),_xlfn._xlws.FILTER('Standings Data'!$K$2:$K$49,'Standings Data'!$A$2:$A$49="H"),1),4,11),"")} -> H4 | Z13: {=IFERROR(INDEX(_xlfn.SORTBY(_xlfn._xlws.FILTER('Standings Data'!$B$2:$M$49,'Standings Data'!$A$2:$A$49="H"),_xlfn._xlws.FILTER('Standings Data'!$K$2:$K$49,'Standings Data'!$A$2:$A$49="H"),1),4,12),"")} | AC13: ='Standings Data'!O12 -> 11 | AD13: ='Standings Data'!P12 -> Congo DR | AE13: ='Standings Data'!Q12 -> K | AF13: ='Standings Data'!R12 -> 4 | AG13: ='Standings Data'!S12 -> 1 | AH13: ='Standings Data'!T12 -> 4 | AI13: ='Standings Data'!U12 -> Likely advances
AC14: ='Standings Data'!O13 -> 12 | AD14: ='Standings Data'!P13 -> Ghana | AE14: ='Standings Data'!Q13 -> L | AF14: ='Standings Data'!R13 -> 4 | AG14: ='Standings Data'!S13 -> 0 | AH14: ='Standings Data'!T13 -> 2 | AI14: ='Standings Data'!U13 -> Likely advances
A15: Group C standings | O15: Group I standings
A16: Team | B16: Pld | C16: W | D16: D | E16: L | F16: GF | G16: GA | H16: GD | I16: Pts | J16: Rank | K16: Position | L16: Advance Status | O16: Team | P16: Pld | Q16: W | R16: D | S16: L | T16: GF | U16: GA | V16: GD | W16: Pts | X16: Rank | Y16: Position | Z16: Advance Status
A17: {=IFERROR(INDEX(_xlfn.SORTBY(_xlfn._xlws.FILTER('Standings Data'!$B$2:$M$49,'Standings Data'!$A$2:$A$49="C"),_xlfn._xlws.FILTER('Standings Data'!$K$2:$K$49,'Standings Data'!$A$2:$A$49="C"),1),1,1),"")} -> Brazil | B17: {=IFERROR(INDEX(_xlfn.SORTBY(_xlfn._xlws.FILTER('Standings Data'!$B$2:$M$49,'Standings Data'!$A$2:$A$49="C"),_xlfn._xlws.FILTER('Standings Data'!$K$2:$K$49,'Standings Data'!$A$2:$A$49="C"),1),1,2),"")} -> 3 | C17: {=IFERROR(INDEX(_xlfn.SORTBY(_xlfn._xlws.FILTER('Standings Data'!$B$2:$M$49,'Standings Data'!$A$2:$A$49="C"),_xlfn._xlws.FILTER('Standings Data'!$K$2:$K$49,'Standings Data'!$A$2:$A$49="C"),1),1,3),"")} -> 2 | D17: {=IFERROR(INDEX(_xlfn.SORTBY(_xlfn._xlws.FILTER('Standings Data'!$B$2:$M$49,'Standings Data'!$A$2:$A$49="C"),_xlfn._xlws.FILTER('Standings Data'!$K$2:$K$49,'Standings Data'!$A$2:$A$49="C"),1),1,4),"")} -> 1 | E17: {=IFERROR(INDEX(_xlfn.SORTBY(_xlfn._xlws.FILTER('Standings Data'!$B$2:$M$49,'Standings Data'!$A$2:$A$49="C"),_xlfn._xlws.FILTER('Standings Data'!$K$2:$K$49,'Standings Data'!$A$2:$A$49="C"),1),1,5),"")} -> 0 | F17: {=IFERROR(INDEX(_xlfn.SORTBY(_xlfn._xlws.FILTER('Standings Data'!$B$2:$M$49,'Standings Data'!$A$2:$A$49="C"),_xlfn._xlws.FILTER('Standings Data'!$K$2:$K$49,'Standings Data'!$A$2:$A$49="C"),1),1,6),"")} -> 7 | G17: {=IFERROR(INDEX(_xlfn.SORTBY(_xlfn._xlws.FILTER('Standings Data'!$B$2:$M$49,'Standings Data'!$A$2:$A$49="C"),_xlfn._xlws.FILTER('Standings Data'!$K$2:$K$49,'Standings Data'!$A$2:$A$49="C"),1),1,7),"")} -> 1 | H17: {=IFERROR(INDEX(_xlfn.SORTBY(_xlfn._xlws.FILTER('Standings Data'!$B$2:$M$49,'Standings Data'!$A$2:$A$49="C"),_xlfn._xlws.FILTER('Standings Data'!$K$2:$K$49,'Standings Data'!$A$2:$A$49="C"),1),1,8),"")} -> 6 | I17: {=IFERROR(INDEX(_xlfn.SORTBY(_xlfn._xlws.FILTER('Standings Data'!$B$2:$M$49,'Standings Data'!$A$2:$A$49="C"),_xlfn._xlws.FILTER('Standings Data'!$K$2:$K$49,'Standings Data'!$A$2:$A$49="C"),1),1,9),"")} -> 7 | J17: {=IFERROR(INDEX(_xlfn.SORTBY(_xlfn._xlws.FILTER('Standings Data'!$B$2:$M$49,'Standings Data'!$A$2:$A$49="C"),_xlfn._xlws.FILTER('Standings Data'!$K$2:$K$49,'Standings Data'!$A$2:$A$49="C"),1),1,10),"")} -> 1 | K17: {=IFERROR(INDEX(_xlfn.SORTBY(_xlfn._xlws.FILTER('Standings Data'!$B$2:$M$49,'Standings Data'!$A$2:$A$49="C"),_xlfn._xlws.FILTER('Standings Data'!$K$2:$K$49,'Standings Data'!$A$2:$A$49="C"),1),1,11),"")} -> C1 | L17: {=IFERROR(INDEX(_xlfn.SORTBY(_xlfn._xlws.FILTER('Standings Data'!$B$2:$M$49,'Standings Data'!$A$2:$A$49="C"),_xlfn._xlws.FILTER('Standings Data'!$K$2:$K$49,'Standings Data'!$A$2:$A$49="C"),1),1,12),"")} -> Qualified | O17: {=IFERROR(INDEX(_xlfn.SORTBY(_xlfn._xlws.FILTER('Standings Data'!$B$2:$M$49,'Standings Data'!$A$2:$A$49="I"),_xlfn._xlws.FILTER('Standings Data'!$K$2:$K$49,'Standings Data'!$A$2:$A$49="I"),1),1,1),"")} -> France | P17: {=IFERROR(INDEX(_xlfn.SORTBY(_xlfn._xlws.FILTER('Standings Data'!$B$2:$M$49,'Standings Data'!$A$2:$A$49="I"),_xlfn._xlws.FILTER('Standings Data'!$K$2:$K$49,'Standings Data'!$A$2:$A$49="I"),1),1,2),"")} -> 3 | Q17: {=IFERROR(INDEX(_xlfn.SORTBY(_xlfn._xlws.FILTER('Standings Data'!$B$2:$M$49,'Standings Data'!$A$2:$A$49="I"),_xlfn._xlws.FILTER('Standings Data'!$K$2:$K$49,'Standings Data'!$A$2:$A$49="I"),1),1,3),"")} -> 3 | R17: {=IFERROR(INDEX(_xlfn.SORTBY(_xlfn._xlws.FILTER('Standings Data'!$B$2:$M$49,'Standings Data'!$A$2:$A$49="I"),_xlfn._xlws.FILTER('Standings Data'!$K$2:$K$49,'Standings Data'!$A$2:$A$49="I"),1),1,4),"")} -> 0 | S17: {=IFERROR(INDEX(_xlfn.SORTBY(_xlfn._xlws.FILTER('Standings Data'!$B$2:$M$49,'Standings Data'!$A$2:$A$49="I"),_xlfn._xlws.FILTER('Standings Data'!$K$2:$K$49,'Standings Data'!$A$2:$A$49="I"),1),1,5),"")} -> 0 | T17: {=IFERROR(INDEX(_xlfn.SORTBY(_xlfn._xlws.FILTER('Standings Data'!$B$2:$M$49,'Standings Data'!$A$2:$A$49="I"),_xlfn._xlws.FILTER('Standings Data'!$K$2:$K$49,'Standings Data'!$A$2:$A$49="I"),1),1,6),"")} -> 10 | U17: {=IFERROR(INDEX(_xlfn.SORTBY(_xlfn._xlws.FILTER('Standings Data'!$B$2:$M$49,'Standings Data'!$A$2:$A$49="I"),_xlfn._xlws.FILTER('Standings Data'!$K$2:$K$49,'Standings Data'!$A$2:$A$49="I"),1),1,7),"")} -> 2 | V17: {=IFERROR(INDEX(_xlfn.SORTBY(_xlfn._xlws.FILTER('Standings Data'!$B$2:$M$49,'Standings Data'!$A$2:$A$49="I"),_xlfn._xlws.FILTER('Standings Data'!$K$2:$K$49,'Standings Data'!$A$2:$A$49="I"),1),1,8),"")} -> 8 | W17: {=IFERROR(INDEX(_xlfn.SORTBY(_xlfn._xlws.FILTER('Standings Data'!$B$2:$M$49,'Standings Data'!$A$2:$A$49="I"),_xlfn._xlws.FILTER('Standings Data'!$K$2:$K$49,'Standings Data'!$A$2:$A$49="I"),1),1,9),"")} -> 9 | X17: {=IFERROR(INDEX(_xlfn.SORTBY(_xlfn._xlws.FILTER('Standings Data'!$B$2:$M$49,'Standings Data'!$A$2:$A$49="I"),_xlfn._xlws.FILTER('Standings Data'!$K$2:$K$49,'Standings Data'!$A$2:$A$49="I"),1),1,10),"")} -> 1 | Y17: {=IFERROR(INDEX(_xlfn.SORTBY(_xlfn._xlws.FILTER('Standings Data'!$B$2:$M$49,'Standings Data'!$A$2:$A$49="I"),_xlfn._xlws.FILTER('Standings Data'!$K$2:$K$49,'Standings Data'!$A$2:$A$49="I"),1),1,11),"")} -> I1 | Z17: {=IFERROR(INDEX(_xlfn.SORTBY(_xlfn._xlws.FILTER('Standings Data'!$B$2:$M$49,'Standings Data'!$A$2:$A$49="I"),_xlfn._xlws.FILTER('Standings Data'!$K$2:$K$49,'Standings Data'!$A$2:$A$49="I"),1),1,12),"")} -> Qualified
